<?xml version="1.0" ?>
<!-- =================================================================================== -->
<!-- |    This document was autogenerated by xacro from /home/pacman/turtlebot3_ws/install/turtlebot3_xacro/share/turtlebot3_xacro/urdf/turtlebot3_waffle_pi.urdf.xacro | -->
<!-- |    EDITING THIS FILE BY HAND IS NOT RECOMMENDED                                 | -->
<!-- =================================================================================== -->
<robot name="turtlebot3_waffle_pi">
	<!-- Init colour -->
	<material name="black">
		<color rgba="0.0 0.0 0.0 1.0"/>
	</material>
	<material name="dark">
		<color rgba="0.3 0.3 0.3 1.0"/>
	</material>
	<material name="light_black">
		<color rgba="0.4 0.4 0.4 1.0"/>
	</material>
	<material name="blue">
		<color rgba="0.0 0.0 0.8 1.0"/>
	</material>
	<material name="green">
		<color rgba="0.0 0.8 0.0 1.0"/>
	</material>
	<material name="grey">
		<color rgba="0.5 0.5 0.5 1.0"/>
	</material>
	<material name="orange">
		<color rgba="1.0 0.4235294117647059 0.0392156862745098 1.0"/>
	</material>
	<material name="brown">
		<color rgba="0.8705882352941177 0.8117647058823529 0.7647058823529411 1.0"/>
	</material>
	<material name="red">
		<color rgba="0.8 0.0 0.0 1.0"/>
	</material>
	<material name="white">
		<color rgba="1.0 1.0 1.0 1.0"/>
	</material>
	<gazebo reference="bot_2/base_link">
		<material>Gazebo/DarkGrey</material>
	</gazebo>
	<gazebo reference="bot_2/wheel_left_link">
		<material>Gazebo/FlatBlack</material>
	</gazebo>
	<gazebo reference="bot_2/wheel_right_link">
		<material>Gazebo/FlatBlack</material>
	</gazebo>
	<gazebo reference="bot_2/caster_back_right_link">
		<material>Gazebo/FlatBlack</material>
	</gazebo>
	<gazebo reference="bot_2/caster_back_left_link">
		<material>Gazebo/FlatBlack</material>
	</gazebo>
	<gazebo reference="bot_2/imu_link">
		<sensor name="tb3_imu" type="imu">
			<always_on>true</always_on>
			<update_rate>50</update_rate>
			<topic>bot_2/imu</topic>
			<gz_frame_id>bot_2/imu_link</gz_frame_id>
			<imu>
				<angular_velocity>
					<x>
						<noise type="gaussian">
							<mean>0.0</mean>
							<stddev>2e-4</stddev>
						</noise>
					</x>
					<y>
						<noise type="gaussian">
							<mean>0.0</mean>
							<stddev>2e-4</stddev>
						</noise>
					</y>
					<z>
						<noise type="gaussian">
							<mean>0.0</mean>
							<stddev>2e-4</stddev>
						</noise>
					</z>
				</angular_velocity>
				<linear_acceleration>
					<x>
						<noise type="gaussian">
							<mean>0.0</mean>
							<stddev>1.7e-2</stddev>
						</noise>
					</x>
					<y>
						<noise type="gaussian">
							<mean>0.0</mean>
							<stddev>1.7e-2</stddev>
						</noise>
					</y>
					<z>
						<noise type="gaussian">
							<mean>0.0</mean>
							<stddev>1.7e-2</stddev>
						</noise>
					</z>
				</linear_acceleration>
			</imu>
		</sensor>
		<material>Gazebo/Grey</material>
	</gazebo>
	<gazebo>
		<plugin filename="libgz-sim-diff-drive-system.so" name="gz::sim::systems::DiffDrive">
			<left_joint>wheel_left_joint</left_joint>
			<right_joint>wheel_right_joint</right_joint>
			<wheel_separation>0.287</wheel_separation>
			<wheel_radius>0.033</wheel_radius>
			<child_frame_id>bot_2/base_footprint</child_frame_id>
		</plugin>
	</gazebo>
	<gazebo reference="bot_2/base_scan">
		<material>Gazebo/FlatBlack</material>
		<sensor name="lds_lfcd_sensor" type="gpu_ray">
			<!--       <pose>0 0 0 0 0 0</pose> -->
			<update_rate>5</update_rate>
			<topic>bot_2/scan</topic>
			<gz_frame_id>bot_2/base_scan</gz_frame_id>
			<ray>
				<scan>
					<horizontal>
						<samples>360</samples>
						<resolution>1</resolution>
						<min_angle>0.0</min_angle>
						<max_angle>6.28319</max_angle>
					</horizontal>
				</scan>
				<range>
					<min>0.120</min>
					<max>3.5</max>
					<resolution>0.015</resolution>
				</range>
				<noise>
					<type>gaussian</type>
					<mean>0.0</mean>
					<stddev>0.01</stddev>
				</noise>
			</ray>
		</sensor>
	</gazebo>
	<gazebo reference="bot_2/camera_rgb_frame">
		<sensor name="pi_camera" type="camera">
			<always_on>true</always_on>
			<camera>
				<optical_frame_id>bot_2/camera_rgb_optical_frame</optical_frame_id>
				<horizontal_fov>1.085595</horizontal_fov>
				<image>
					<width>640</width>
					<height>480</height>
					<format>R8G8B8</format>
				</image>
				<clip>
					<near>0.03</near>
					<far>100</far>
				</clip>
			</camera>
			<topic>bot_2/image</topic>
			<enable_metrics>false</enable_metrics>
		</sensor>
	</gazebo>
	<gazebo>
		<plugin filename="libignition-gazebo-joint-state-publisher-system.so" name="ignition::gazebo::systems::JointStatePublisher"/>
		<plugin filename="ignition-gazebo-pose-publisher-system" name="ignition::gazebo::systems::PosePublisher">
			<publish_link_pose>false</publish_link_pose>
			<publish_collision_pose>false</publish_collision_pose>
			<publish_visual_pose>false</publish_visual_pose>
			<publish_nested_model_pose>true</publish_nested_model_pose>
		</plugin>
	</gazebo>
	<link name="bot_2/base_footprint"/>
	<joint name="base_joint" type="fixed">
		<parent link="bot_2/base_footprint"/>
		<child link="bot_2/base_link"/>
		<origin rpy="0 0 0" xyz="0 0 0.010"/>
	</joint>
	<link name="bot_2/base_link">
		<visual>
			<origin rpy="0 0 0" xyz="-0.064 0 0.0"/>
			<geometry>
				<mesh filename="package://turtlebot3_xacro/meshes/bases/waffle_pi_base.stl" scale="0.001 0.001 0.001"/>
			</geometry>
			<material name="light_black"/>
		</visual>
		<collision>
			<origin rpy="0 0 0" xyz="-0.064 0 0.047"/>
			<geometry>
				<box size="0.266 0.266 0.094"/>
			</geometry>
		</collision>
		<inertial>
			<mass value="1.3729096e+00"/>
			<inertia ixx="8.7002718e-03" ixy="-4.7576583e-05" ixz="1.1160499e-04" iyy="8.6195418e-03" iyz="-3.5422299e-06" izz="1.4612727e-02"/>
		</inertial>
	</link>
	<joint name="wheel_left_joint" type="continuous">
		<parent link="bot_2/base_link"/>
		<child link="bot_2/wheel_left_link"/>
		<origin rpy="-1.57 0 0" xyz="0.0 0.144 0.023"/>
		<axis xyz="0 0 1"/>
		<limit effort="10" velocity="7.88"/>
	</joint>
	<link name="bot_2/wheel_left_link">
		<visual>
			<origin rpy="1.57 0 0" xyz="0 0 0"/>
			<geometry>
				<mesh filename="package://turtlebot3_xacro/meshes/wheels/left_tire.stl" scale="0.001 0.001 0.001"/>
			</geometry>
			<material name="dark"/>
		</visual>
		<collision>
			<geometry>
				<cylinder length="0.018" radius="0.033"/>
			</geometry>
			<surface>
				<friction>
					<ode>
						<mu>1</mu>
						<mu2>0</mu2>
					</ode>
				</friction>
			</surface>
		</collision>
		<inertial>
			<origin xyz="0 0 0"/>
			<mass value="2.8498940e-02"/>
			<inertia ixx="1.1175580e-05" ixy="-4.2369783e-11" ixz="-5.9381719e-09" iyy="1.1192413e-05" iyz="-1.4400107e-11" izz="2.0712558e-05"/>
		</inertial>
	</link>
	<joint name="wheel_right_joint" type="continuous">
		<parent link="bot_2/base_link"/>
		<child link="bot_2/wheel_right_link"/>
		<origin rpy="-1.57 0 0" xyz="0.0 -0.144 0.023"/>
		<axis xyz="0 0 1"/>
		<limit effort="10" velocity="7.88"/>
	</joint>
	<link name="bot_2/wheel_right_link">
		<visual>
			<origin rpy="1.57 0 0" xyz="0 0 0"/>
			<geometry>
				<mesh filename="package://turtlebot3_xacro/meshes/wheels/right_tire.stl" scale="0.001 0.001 0.001"/>
			</geometry>
			<material name="dark"/>
		</visual>
		<collision>
			<geometry>
				<cylinder length="0.018" radius="0.033"/>
			</geometry>
			<surface>
				<friction>
					<ode>
						<mu>1</mu>
						<mu2>0</mu2>
					</ode>
				</friction>
			</surface>
		</collision>
		<inertial>
			<origin xyz="0 0 0"/>
			<mass value="2.8498940e-02"/>
			<inertia ixx="1.1175580e-05" ixy="-4.2369783e-11" ixz="-5.9381719e-09" iyy="1.1192413e-05" iyz="-1.4400107e-11" izz="2.0712558e-05"/>
		</inertial>
	</link>
	<joint name="caster_back_right_joint" type="fixed">
		<parent link="bot_2/base_link"/>
		<child link="bot_2/caster_back_right_link"/>
		<origin rpy="-1.57 0 0" xyz="-0.177 -0.064 -0.004"/>
	</joint>
	<link name="bot_2/caster_back_right_link">
		<collision>
			<origin rpy="0 0 0" xyz="0 0.001 0"/>
			<geometry>
				<!--         <box size="0.030 0.009 0.020"/> -->
				<sphere radius="0.009"/>
			</geometry>
			<surface>
				<friction>
					<ode>
						<mu>0</mu>
						<mu2>0</mu2>
					</ode>
				</friction>
			</surface>
		</collision>
		<inertial>
			<origin xyz="0 0 0"/>
			<mass value="0.005"/>
			<inertia ixx="0.001" ixy="0.0" ixz="0.0" iyy="0.001" iyz="0.0" izz="0.001"/>
		</inertial>
	</link>
	<joint name="caster_back_left_joint" type="fixed">
		<parent link="bot_2/base_link"/>
		<child link="bot_2/caster_back_left_link"/>
		<origin rpy="-1.57 0 0" xyz="-0.177 0.064 -0.004"/>
	</joint>
	<link name="bot_2/caster_back_left_link">
		<collision>
			<origin rpy="0 0 0" xyz="0 0.001 0"/>
			<geometry>
				<!--         <box size="0.030 0.009 0.020"/> -->
				<sphere radius="0.009"/>
			</geometry>
			<surface>
				<friction>
					<ode>
						<mu>0</mu>
						<mu2>0</mu2>
					</ode>
				</friction>
			</surface>
		</collision>
		<inertial>
			<origin xyz="0 0 0"/>
			<mass value="0.005"/>
			<inertia ixx="0.001" ixy="0.0" ixz="0.0" iyy="0.001" iyz="0.0" izz="0.001"/>
		</inertial>
	</link>
	<joint name="imu_joint" type="fixed">
		<parent link="bot_2/base_link"/>
		<child link="bot_2/imu_link"/>
		<origin rpy="0 0 0" xyz="0.0 0 0.068"/>
	</joint>
	<link name="bot_2/imu_link">
		<inertial>
			<mass value="0.001"/>
			<inertia ixx="0.00000542" ixy="0.0" ixz="0.0" iyy="0.00002104" iyz="0.0" izz="0.00002604"/>
		</inertial>
	</link>
	<joint name="scan_joint" type="fixed">
		<parent link="bot_2/base_link"/>
		<child link="bot_2/base_scan"/>
		<origin rpy="0 0 0" xyz="-0.064 0 0.122"/>
	</joint>
	<link name="bot_2/base_scan">
		<visual>
			<origin rpy="0 0 0" xyz="0 0 0.0"/>
			<geometry>
				<mesh filename="package://turtlebot3_xacro/meshes/sensors/lds.stl" scale="0.001 0.001 0.001"/>
			</geometry>
			<material name="dark"/>
		</visual>
		<collision>
			<origin rpy="0 0 0" xyz="0.015 0 -0.0065"/>
			<geometry>
				<cylinder length="0.0315" radius="0.055"/>
			</geometry>
		</collision>
		<inertial>
			<mass value="0.114"/>
			<origin xyz="0 0 0"/>
			<inertia ixx="0.001" ixy="0.0" ixz="0.0" iyy="0.001" iyz="0.0" izz="0.001"/>
		</inertial>
	</link>
	<joint name="camera_joint" type="fixed">
		<origin rpy="0 0 0" xyz="0.073 -0.011 0.084"/>
		<parent link="bot_2/base_link"/>
		<child link="bot_2/camera_link"/>
	</joint>
	<link name="bot_2/camera_link">
		<collision>
			<origin rpy="0 0 0" xyz="0.005 0.011 0.013"/>
			<geometry>
				<box size="0.015 0.030 0.027"/>
			</geometry>
		</collision>
	</link>
	<joint name="camera_rgb_joint" type="fixed">
		<origin rpy="0 0 0" xyz="0.003 0.011 0.009"/>
		<parent link="bot_2/camera_link"/>
		<child link="bot_2/camera_rgb_frame"/>
	</joint>
	<link name="bot_2/camera_rgb_frame"/>
	<joint name="camera_rgb_optical_joint" type="fixed">
		<origin rpy="-1.57 0 -1.57" xyz="0 0 0"/>
		<parent link="bot_2/camera_rgb_frame"/>
		<child link="bot_2/camera_rgb_optical_frame"/>
	</joint>
	<link name="bot_2/camera_rgb_optical_frame"/>
</robot>
